<?xml version="1.0" ?> <!-- =================================================================================== --> <!-- |    This document was autogenerated by xacro from /home/malasiot/ros_ws/install/iiwa_description/share/iiwa_description/config/iiwa_dual.config.xacro | --> <!-- |    EDITING THIS FILE BY HAND IS NOT RECOMMENDED                                 | --> <!-- =================================================================================== --> <!-- Kuka iiwa 7DoF manipulator --> <robot name="iiwa"> <!-- Used for fixing robot --> <link name="world"/> <gazebo reference="world"> <static>true</static> </gazebo> <gazebo reference="base"> <static>true</static> </gazebo> <gazebo reference="camera_pole"> <static>true</static> </gazebo> <gazebo reference="camera"> <static>true</static> </gazebo> <material name="gray"> <color rgba="0.5 0.5 0.5 1.0"/> </material> <joint name="marker_joint_r_tool0" type="fixed"> <parent link="r_tool0"/> <child link="marker_link_0"/> <origin rpy="0 1.57 0" xyz="0 0.0 0.1"/> </joint> <!-- LINK 0 --> <link name="marker_link_0"> <inertial> <origin rpy="0 0 0" xyz="0 0 0"/> <mass value="1.0"/> <inertia ixx="0.0741666666667" ixy="0.0" ixz="0.0" iyy="0.0585416666667" iyz="0.0" izz="0.0260416666667"/> </inertial> <collision> <origin rpy="0 0 0" xyz="0 0 0"/> <geometry> <box size="0.2 0.2 0.022222222222222223"/> </geometry> </collision> <visual> <origin rpy="0 0 0" xyz="0 0 0"/> <geometry> <box size="0.2 0.2 0.022222222222222223"/> </geometry> <material name="white"> <color rgba="1 1 1 1"/> </material> </visual> <visual> <origin rpy="0.0 0 0" xyz="0 0 0"/> <geometry> <!-- <box size="0.09 0.09 0.01"/> --> <mesh filename="package://iiwa_description/meshes/aruco/aruco.dae" scale="2.2222222222222223 2.2222222222222223 2.2222222222222223"/> </geometry> </visual> </link> <link name="marker_link_origin"/> <joint name="marker_joint_origin_link0" type="fixed"> <parent link="marker_link_0"/> <child link="marker_link_origin"/> <origin rpy="0 0 3.14" xyz="0.08571428571428572 0.08571428571428572 0.011111111111111112"/> </joint> <gazebo reference="marker_link_0"> <kp>100000.0</kp> <kd>100000.0</kd> <mu1>0.1</mu1> <mu2>0.1</mu2> <fdir1>1 0 0</fdir1> </gazebo> <!-- table as base for the 2 iiwa's --> <link name="base"> <visual> <origin rpy="0 0 0" xyz="-0.5 0 -0.005"/> <geometry> <box size="1.5 1 0.01"/> </geometry> <material name="White"> <color rgba="1.0 1.0 1.0 1.0"/> </material> </visual> <collision> <origin rpy="0 0 0" xyz="-0.5 0 -0.005"/> <geometry> <box size="1.5 1 0.01"/> </geometry> </collision> <inertial> <origin rpy="0.0 0.0 0.0" xyz="0.0 0.0 0.0"/> <mass value="10.0"/> <inertia ixx="0.001" ixy="0.0" ixz="0.001" iyy="0.0" iyz="0.0" izz="0.001"/> </inertial> </link> <joint name="base_to_world" type="fixed"> <parent link="world"/> <child link="base"/> <origin rpy="0.0 0.0 0.0" xyz="0.0 0.0 0.0"/> </joint> <link name="camera_pole"> <visual> <origin rpy="0 0 0" xyz="0 0 0.6"/> <geometry> <box size="0.025 0.025 1.2"/> </geometry> <material name="White"> <color rgba="1.0 1.0 1.0 1.0"/> </material> </visual> <collision> <origin rpy="0 0 0" xyz="0 0 0.6"/> <geometry> <box size="0.025 0.025 1.2"/> </geometry> </collision> <inertial> <origin rpy="0.0 0.0 0.0" xyz="0.0 0.0 0.0"/> <mass value="1.0"/> <inertia ixx="0.001" ixy="0.0" ixz="0.001" iyy="0.0" iyz="0.0" izz="0.001"/> </inertial> </link> <joint name="camera_pole_to_world" type="fixed"> <parent link="base"/> <child link="camera_pole"/> <origin rpy="0.0 0.0 0.0" xyz="0.0 0.0 0.0"/> </joint> <link name="camera"> <visual> <geometry> <box size="0.02 0.1 0.05"/> </geometry> <material name="Red"> <color rgba="0.5 0.0 0.5 1.0"/> </material> </visual> <collision> <geometry> <box size="0.02 0.1 0.05"/> </geometry> </collision> <inertial> <origin rpy="0.0 0.0 0.0" xyz="0.0 0.0 0.0"/> <mass value="1.0"/> <inertia ixx="0.001" ixy="0.0" ixz="0.001" iyy="0.0" iyz="0.0" izz="0.001"/> </inertial> </link> <joint name="camera_to_pole" type="fixed"> <parent link="camera_pole"/> <child link="camera"/> <origin rpy="0 -0.8 0" xyz="-0.025 0 1.15"/> </joint> <link name="camera_optical_frame"/> <joint name="camera_optical_frame_to_camera" type="fixed"> <parent link="camera"/> <child link="camera_optical_frame"/> <origin rpy="-1.57 0 1.57" xyz="-0.025 0 0"/> </joint> <link name="l_iiwa_base" type="fixed"/> <joint name="l_iiwa_root_joint" type="fixed"> <origin rpy="0.0 0.0 0.0" xyz="0.0 0.36 0.0"/> <parent link="base"/> <child link="l_iiwa_base"/> </joint> <joint name="l_iiwa_base_joint" type="fixed"> <origin rpy="0.0 0 0" xyz="0 0 0"/> <parent link="l_iiwa_base"/> <child link="l_link_0"/> </joint> <link name="l_link_0"> <visual> <origin rpy="0.0 0 0" xyz="0 0 0"/> <geometry> <mesh filename="package://iiwa_description/meshes/lbr_iiwa_14_r820/visual/base_link.dae"/> </geometry> </visual> <collision> <origin rpy="0 0 0" xyz="0 0 0"/> <geometry> <mesh filename="package://iiwa_description/meshes/lbr_iiwa_14_r820/collision/base_link.stl"/> </geometry> </collision> <inertial> <origin rpy="0 0 0" xyz="-0.1 0 0.07"/> <mass value="5"/> <inertia ixx="0.05" ixy="0" ixz="0" iyy="0.06" iyz="0" izz="0.03"/> </inertial> </link> <link name="l_link_1"> <visual> <origin rpy="0 0 0" xyz="0 0 0"/> <geometry> <mesh filename="package://iiwa_description/meshes/lbr_iiwa_14_r820/visual/link_1.dae"/> </geometry> </visual> <collision> <origin rpy="0 0 0" xyz="0 0 0"/> <geometry> <mesh filename="package://iiwa_description/meshes/lbr_iiwa_14_r820/collision/link_1.stl"/> </geometry> </collision> <inertial> <origin rpy="0 0 0" xyz="0 -0.03 0.12"/> <mass value="4"/> <inertia ixx="0.1" ixy="0" ixz="0" iyy="0.09" iyz="0" izz="0.02"/> </inertial> </link> <link name="l_link_2"> <visual> <origin rpy="0 0 0" xyz="0 0 0"/> <geometry> <mesh filename="package://iiwa_description/meshes/lbr_iiwa_14_r820/visual/link_2.dae"/> </geometry> </visual> <collision> <origin rpy="0 0 0" xyz="0 0 0"/> <geometry> <mesh filename="package://iiwa_description/meshes/lbr_iiwa_14_r820/collision/link_2.stl"/> </geometry> </collision> <inertial> <origin rpy="0 0 0" xyz="0.0003 0.059 0.042"/> <mass value="4"/> <inertia ixx="0.05" ixy="0" ixz="0" iyy="0.018" iyz="0" izz="0.044"/> </inertial> </link> <link name="l_link_3"> <visual> <origin rpy="0 0 0" xyz="0 0 0"/> <geometry> <mesh filename="package://iiwa_description/meshes/lbr_iiwa_14_r820/visual/link_3.dae"/> </geometry> </visual> <collision> <origin rpy="0 0 0" xyz="0 0 0"/> <geometry> <mesh filename="package://iiwa_description/meshes/lbr_iiwa_14_r820/collision/link_3.stl"/> </geometry> </collision> <inertial> <origin rpy="0 0 0" xyz="0 0.03 0.13"/> <mass value="3"/> <inertia ixx="0.08" ixy="0" ixz="0" iyy="0.075" iyz="0" izz="0.01"/> </inertial> </link> <link name="l_link_4"> <visual> <origin rpy="0 0 0" xyz="0 0 0"/> <geometry> <mesh filename="package://iiwa_description/meshes/lbr_iiwa_14_r820/visual/link_4.dae"/> </geometry> </visual> <collision> <origin rpy="0 0 0" xyz="0 0 0"/> <geometry> <mesh filename="package://iiwa_description/meshes/lbr_iiwa_14_r820/collision/link_4.stl"/> </geometry> </collision> <inertial> <origin rpy="0 0 0" xyz="0 0.067 0.034"/> <mass value="2.7"/> <inertia ixx="0.03" ixy="0" ixz="0" iyy="0.01" iyz="0" izz="0.029"/> </inertial> </link> <link name="l_link_5"> <visual> <origin rpy="0 0 0" xyz="0 0 0"/> <geometry> <mesh filename="package://iiwa_description/meshes/lbr_iiwa_14_r820/visual/link_5.dae"/> </geometry> </visual> <collision> <origin rpy="0 0 0" xyz="0 0 0"/> <geometry> <mesh filename="package://iiwa_description/meshes/lbr_iiwa_14_r820/collision/link_5.stl"/> </geometry> </collision> <inertial> <origin rpy="0 0 0" xyz="0.0001 0.021 0.076"/> <mass value="1.7"/> <inertia ixx="0.02" ixy="0" ixz="0" iyy="0.018" iyz="0" izz="0.005"/> </inertial> </link> <link name="l_link_6"> <visual> <origin rpy="0 0 0" xyz="0 0 0"/> <geometry> <mesh filename="package://iiwa_description/meshes/lbr_iiwa_14_r820/visual/link_6.dae"/> </geometry> </visual> <collision> <origin rpy="0 0 0" xyz="0 0 0"/> <geometry> <mesh filename="package://iiwa_description/meshes/lbr_iiwa_14_r820/collision/link_6.stl"/> </geometry> </collision> <inertial> <origin rpy="0 0 0" xyz="0 0.0006 0.0004"/> <mass value="1.8"/> <inertia ixx="0.025" ixy="0" ixz="0" iyy="0.0136" iyz="0" izz="0.0247"/> </inertial> </link> <link name="l_link_7"> <visual> <origin rpy="0 0 0" xyz="0 0 0.07"/> <material name="gray"/> <geometry> <mesh filename="package://iiwa_description/meshes/lbr_iiwa_14_r820/visual/link_7_2.stl" scale="0.001 0.001 0.001"/> </geometry> </visual> <collision> <origin rpy="0 0 0" xyz="0 0 0.07"/> <geometry> <mesh filename="package://iiwa_description/meshes/lbr_iiwa_14_r820/collision/link_7_2.stl" scale="0.001 0.001 0.001"/> </geometry> </collision> <inertial> <origin rpy="0 0 0" xyz="0 0 0.02"/> <mass value="0.42857142857142855"/> <!--this is for the MFT Pneumatisch flange--> <inertia ixx="0.01" ixy="0" ixz="0" iyy="0.01" iyz="0" izz="0.01"/> </inertial> </link> <link name="l_tool0"/> <joint name="l_joint_a1" type="revolute"> <origin rpy="0 0 0" xyz="0 0 0"/> <parent link="l_link_0"/> <child link="l_link_1"/> <axis xyz="0 0 1"/> <limit effort="320" lower="-2.9668" upper="2.9668" velocity="1.4834"/> </joint> <joint name="l_joint_a2" type="revolute"> <origin rpy="0 0 0" xyz="-0.00043624 0 0.36"/> <parent link="l_link_1"/> <child link="l_link_2"/> <axis xyz="0 1 0"/> <limit effort="320" lower="-2.0942" upper="2.0942" velocity="1.4834"/> </joint> <joint name="l_joint_a3" type="revolute"> <origin rpy="0 0 0" xyz="0 0 0"/> <parent link="l_link_2"/> <child link="l_link_3"/> <axis xyz="0 0 1"/> <limit effort="176" lower="-2.9668" upper="2.9668" velocity="1.7452"/> </joint> <joint name="l_joint_a4" type="revolute"> <origin rpy="0 0 0" xyz="0.00043624 0 0.42"/> <parent link="l_link_3"/> <child link="l_link_4"/> <axis xyz="0 -1 0"/> <limit effort="176" lower="-2.0942" upper="2.0942" velocity="1.3089"/> </joint> <joint name="l_joint_a5" type="revolute"> <origin rpy="0 0 0" xyz="0 0 0"/> <parent link="l_link_4"/> <child link="l_link_5"/> <axis xyz="0 0 1"/> <limit effort="110" lower="-2.9668" upper="2.9668" velocity="2.2688"/> </joint> <joint name="l_joint_a6" type="revolute"> <origin rpy="0 0 0" xyz="0 0 0.4"/> <parent link="l_link_5"/> <child link="l_link_6"/> <axis xyz="0 1 0"/> <limit effort="40" lower="-2.0942" upper="2.0942" velocity="2.356"/> </joint> <joint name="l_joint_a7" type="revolute"> <origin rpy="0 0 0" xyz="0 0 0"/> <parent link="l_link_6"/> <child link="l_link_7"/> <axis xyz="0 0 1"/> <limit effort="40" lower="-3.0541" upper="3.0541" velocity="2.356"/> </joint> <joint name="l_joint_a7-tool0" type="fixed"> <origin rpy="0 0 0" xyz="0 0 0.154"/> <parent link="l_link_7"/> <child link="l_tool0"/> <axis xyz="0 0 0"/> </joint> <link name="r_iiwa_base" type="fixed"/> <joint name="r_iiwa_root_joint" type="fixed"> <origin rpy="0.0 0.0 0.0" xyz="0.0 -0.36 0.0"/> <parent link="base"/> <child link="r_iiwa_base"/> </joint> <joint name="r_iiwa_base_joint" type="fixed"> <origin rpy="0.0 0 0" xyz="0 0 0"/> <parent link="r_iiwa_base"/> <child link="r_link_0"/> </joint> <link name="r_link_0"> <visual> <origin rpy="0.0 0 0" xyz="0 0 0"/> <geometry> <mesh filename="package://iiwa_description/meshes/lbr_iiwa_14_r820/visual/base_link.dae"/> </geometry> </visual> <collision> <origin rpy="0 0 0" xyz="0 0 0"/> <geometry> <mesh filename="package://iiwa_description/meshes/lbr_iiwa_14_r820/collision/base_link.stl"/> </geometry> </collision> <inertial> <origin rpy="0 0 0" xyz="-0.1 0 0.07"/> <mass value="5"/> <inertia ixx="0.05" ixy="0" ixz="0" iyy="0.06" iyz="0" izz="0.03"/> </inertial> </link> <link name="r_link_1"> <visual> <origin rpy="0 0 0" xyz="0 0 0"/> <geometry> <mesh filename="package://iiwa_description/meshes/lbr_iiwa_14_r820/visual/link_1.dae"/> </geometry> </visual> <collision> <origin rpy="0 0 0" xyz="0 0 0"/> <geometry> <mesh filename="package://iiwa_description/meshes/lbr_iiwa_14_r820/collision/link_1.stl"/> </geometry> </collision> <inertial> <origin rpy="0 0 0" xyz="0 -0.03 0.12"/> <mass value="4"/> <inertia ixx="0.1" ixy="0" ixz="0" iyy="0.09" iyz="0" izz="0.02"/> </inertial> </link> <link name="r_link_2"> <visual> <origin rpy="0 0 0" xyz="0 0 0"/> <geometry> <mesh filename="package://iiwa_description/meshes/lbr_iiwa_14_r820/visual/link_2.dae"/> </geometry> </visual> <collision> <origin rpy="0 0 0" xyz="0 0 0"/> <geometry> <mesh filename="package://iiwa_description/meshes/lbr_iiwa_14_r820/collision/link_2.stl"/> </geometry> </collision> <inertial> <origin rpy="0 0 0" xyz="0.0003 0.059 0.042"/> <mass value="4"/> <inertia ixx="0.05" ixy="0" ixz="0" iyy="0.018" iyz="0" izz="0.044"/> </inertial> </link> <link name="r_link_3"> <visual> <origin rpy="0 0 0" xyz="0 0 0"/> <geometry> <mesh filename="package://iiwa_description/meshes/lbr_iiwa_14_r820/visual/link_3.dae"/> </geometry> </visual> <collision> <origin rpy="0 0 0" xyz="0 0 0"/> <geometry> <mesh filename="package://iiwa_description/meshes/lbr_iiwa_14_r820/collision/link_3.stl"/> </geometry> </collision> <inertial> <origin rpy="0 0 0" xyz="0 0.03 0.13"/> <mass value="3"/> <inertia ixx="0.08" ixy="0" ixz="0" iyy="0.075" iyz="0" izz="0.01"/> </inertial> </link> <link name="r_link_4"> <visual> <origin rpy="0 0 0" xyz="0 0 0"/> <geometry> <mesh filename="package://iiwa_description/meshes/lbr_iiwa_14_r820/visual/link_4.dae"/> </geometry> </visual> <collision> <origin rpy="0 0 0" xyz="0 0 0"/> <geometry> <mesh filename="package://iiwa_description/meshes/lbr_iiwa_14_r820/collision/link_4.stl"/> </geometry> </collision> <inertial> <origin rpy="0 0 0" xyz="0 0.067 0.034"/> <mass value="2.7"/> <inertia ixx="0.03" ixy="0" ixz="0" iyy="0.01" iyz="0" izz="0.029"/> </inertial> </link> <link name="r_link_5"> <visual> <origin rpy="0 0 0" xyz="0 0 0"/> <geometry> <mesh filename="package://iiwa_description/meshes/lbr_iiwa_14_r820/visual/link_5.dae"/> </geometry> </visual> <collision> <origin rpy="0 0 0" xyz="0 0 0"/> <geometry> <mesh filename="package://iiwa_description/meshes/lbr_iiwa_14_r820/collision/link_5.stl"/> </geometry> </collision> <inertial> <origin rpy="0 0 0" xyz="0.0001 0.021 0.076"/> <mass value="1.7"/> <inertia ixx="0.02" ixy="0" ixz="0" iyy="0.018" iyz="0" izz="0.005"/> </inertial> </link> <link name="r_link_6"> <visual> <origin rpy="0 0 0" xyz="0 0 0"/> <geometry> <mesh filename="package://iiwa_description/meshes/lbr_iiwa_14_r820/visual/link_6.dae"/> </geometry> </visual> <collision> <origin rpy="0 0 0" xyz="0 0 0"/> <geometry> <mesh filename="package://iiwa_description/meshes/lbr_iiwa_14_r820/collision/link_6.stl"/> </geometry> </collision> <inertial> <origin rpy="0 0 0" xyz="0 0.0006 0.0004"/> <mass value="1.8"/> <inertia ixx="0.025" ixy="0" ixz="0" iyy="0.0136" iyz="0" izz="0.0247"/> </inertial> </link> <link name="r_link_7"> <visual> <origin rpy="0 0 0" xyz="0 0 0.07"/> <material name="gray"/> <geometry> <mesh filename="package://iiwa_description/meshes/lbr_iiwa_14_r820/visual/link_7_2.stl" scale="0.001 0.001 0.001"/> </geometry> </visual> <collision> <origin rpy="0 0 0" xyz="0 0 0.07"/> <geometry> <mesh filename="package://iiwa_description/meshes/lbr_iiwa_14_r820/collision/link_7_2.stl" scale="0.001 0.001 0.001"/> </geometry> </collision> <inertial> <origin rpy="0 0 0" xyz="0 0 0.02"/> <mass value="0.42857142857142855"/> <!--this is for the MFT Pneumatisch flange--> <inertia ixx="0.01" ixy="0" ixz="0" iyy="0.01" iyz="0" izz="0.01"/> </inertial> </link> <link name="r_tool0"/> <joint name="r_joint_a1" type="revolute"> <origin rpy="0 0 0" xyz="0 0 0"/> <parent link="r_link_0"/> <child link="r_link_1"/> <axis xyz="0 0 1"/> <limit effort="320" lower="-2.9668" upper="2.9668" velocity="1.4834"/> </joint> <joint name="r_joint_a2" type="revolute"> <origin rpy="0 0 0" xyz="-0.00043624 0 0.36"/> <parent link="r_link_1"/> <child link="r_link_2"/> <axis xyz="0 1 0"/> <limit effort="320" lower="-2.0942" upper="2.0942" velocity="1.4834"/> </joint> <joint name="r_joint_a3" type="revolute"> <origin rpy="0 0 0" xyz="0 0 0"/> <parent link="r_link_2"/> <child link="r_link_3"/> <axis xyz="0 0 1"/> <limit effort="176" lower="-2.9668" upper="2.9668" velocity="1.7452"/> </joint> <joint name="r_joint_a4" type="revolute"> <origin rpy="0 0 0" xyz="0.00043624 0 0.42"/> <parent link="r_link_3"/> <child link="r_link_4"/> <axis xyz="0 -1 0"/> <limit effort="176" lower="-2.0942" upper="2.0942" velocity="1.3089"/> </joint> <joint name="r_joint_a5" type="revolute"> <origin rpy="0 0 0" xyz="0 0 0"/> <parent link="r_link_4"/> <child link="r_link_5"/> <axis xyz="0 0 1"/> <limit effort="110" lower="-2.9668" upper="2.9668" velocity="2.2688"/> </joint> <joint name="r_joint_a6" type="revolute"> <origin rpy="0 0 0" xyz="0 0 0.4"/> <parent link="r_link_5"/> <child link="r_link_6"/> <axis xyz="0 1 0"/> <limit effort="40" lower="-2.0942" upper="2.0942" velocity="2.356"/> </joint> <joint name="r_joint_a7" type="revolute"> <origin rpy="0 0 0" xyz="0 0 0"/> <parent link="r_link_6"/> <child link="r_link_7"/> <axis xyz="0 0 1"/> <limit effort="40" lower="-3.0541" upper="3.0541" velocity="2.356"/> </joint> <joint name="r_joint_a7-tool0" type="fixed"> <origin rpy="0 0 0" xyz="0 0 0.154"/> <parent link="r_link_7"/> <child link="r_tool0"/> <axis xyz="0 0 0"/> </joint> <ros2_control name="iiwa_left" type="system"> <hardware> <plugin>fake_components/GenericSystem</plugin> <param name="state_following_offset">0.0</param> </hardware> <joint name="l_joint_a1"> <command_interface name="position"/> <param name="min">-2.96</param> <param name="max">2.96</param> <state_interface name="position"> <param name="initial_value">0.0</param> </state_interface> <state_interface name="velocity"> <param name="initial_value">0.0</param> </state_interface> <state_interface name="effort"> <param name="initial_value">0.0</param> </state_interface> </joint> <joint name="l_joint_a2"> <command_interface name="position"/> <param name="min">-2.09</param> <param name="max">2.09</param> <state_interface name="position"> <param name="initial_value">-0.7854</param> </state_interface> <state_interface name="velocity"> <param name="initial_value">0.0</param> </state_interface> <state_interface name="effort"> <param name="initial_value">0.0</param> </state_interface> </joint> <joint name="l_joint_a3"> <command_interface name="position"/> <param name="min">-2.96</param> <param name="max">2.96</param> <state_interface name="position"> <param name="initial_value">0.0</param> </state_interface> <state_interface name="velocity"> <param name="initial_value">0.0</param> </state_interface> <state_interface name="effort"> <param name="initial_value">0.0</param> </state_interface> </joint> <joint name="l_joint_a4"> <command_interface name="position"/> <param name="min">-2.09</param> <param name="max">2.09</param> <state_interface name="position"> <param name="initial_value">1.3962</param> </state_interface> <state_interface name="velocity"> <param name="initial_value">0.0</param> </state_interface> <state_interface name="effort"> <param name="initial_value">0.0</param> </state_interface> </joint> <joint name="l_joint_a5"> <command_interface name="position"/> <param name="min">-2.96</param> <param name="max">2.96</param> <state_interface name="position"> <param name="initial_value">0.0</param> </state_interface> <state_interface name="velocity"> <param name="initial_value">0.0</param> </state_interface> <state_interface name="effort"> <param name="initial_value">0.0</param> </state_interface> </joint> <joint name="l_joint_a6"> <command_interface name="position"/> <param name="min">-2.09</param> <param name="max">2.09</param> <state_interface name="position"> <param name="initial_value">0.6109</param> </state_interface> <state_interface name="velocity"> <param name="initial_value">0.0</param> </state_interface> <state_interface name="effort"> <param name="initial_value">0.0</param> </state_interface> </joint> <joint name="l_joint_a7"> <command_interface name="position"/> <param name="min">-3.05</param> <param name="max">3.05</param> <state_interface name="position"> <param name="initial_value">0.0</param> </state_interface> <state_interface name="velocity"> <param name="initial_value">0.0</param> </state_interface> <state_interface name="effort"> <param name="initial_value">0.0</param> </state_interface> </joint> <sensor name="l_external_torque_sensor"> <state_interface name="external_torque.joint_a1"/> <state_interface name="external_torque.joint_a2"/> <state_interface name="external_torque.joint_a3"/> <state_interface name="external_torque.joint_a4"/> <state_interface name="external_torque.joint_a5"/> <state_interface name="external_torque.joint_a6"/> <state_interface name="external_torque.joint_a7"/> </sensor> </ros2_control> <ros2_control name="iiwa_right" type="system"> <hardware> <plugin>fake_components/GenericSystem</plugin> <param name="state_following_offset">0.0</param> </hardware> <joint name="r_joint_a1"> <command_interface name="position"/> <param name="min">-2.96</param> <param name="max">2.96</param> <state_interface name="position"> <param name="initial_value">0.0</param> </state_interface> <state_interface name="velocity"> <param name="initial_value">0.0</param> </state_interface> <state_interface name="effort"> <param name="initial_value">0.0</param> </state_interface> </joint> <joint name="r_joint_a2"> <command_interface name="position"/> <param name="min">-2.09</param> <param name="max">2.09</param> <state_interface name="position"> <param name="initial_value">-0.7854</param> </state_interface> <state_interface name="velocity"> <param name="initial_value">0.0</param> </state_interface> <state_interface name="effort"> <param name="initial_value">0.0</param> </state_interface> </joint> <joint name="r_joint_a3"> <command_interface name="position"/> <param name="min">-2.96</param> <param name="max">2.96</param> <state_interface name="position"> <param name="initial_value">0.0</param> </state_interface> <state_interface name="velocity"> <param name="initial_value">0.0</param> </state_interface> <state_interface name="effort"> <param name="initial_value">0.0</param> </state_interface> </joint> <joint name="r_joint_a4"> <command_interface name="position"/> <param name="min">-2.09</param> <param name="max">2.09</param> <state_interface name="position"> <param name="initial_value">1.3962</param> </state_interface> <state_interface name="velocity"> <param name="initial_value">0.0</param> </state_interface> <state_interface name="effort"> <param name="initial_value">0.0</param> </state_interface> </joint> <joint name="r_joint_a5"> <command_interface name="position"/> <param name="min">-2.96</param> <param name="max">2.96</param> <state_interface name="position"> <param name="initial_value">0.0</param> </state_interface> <state_interface name="velocity"> <param name="initial_value">0.0</param> </state_interface> <state_interface name="effort"> <param name="initial_value">0.0</param> </state_interface> </joint> <joint name="r_joint_a6"> <command_interface name="position"/> <param name="min">-2.09</param> <param name="max">2.09</param> <state_interface name="position"> <param name="initial_value">0.6109</param> </state_interface> <state_interface name="velocity"> <param name="initial_value">0.0</param> </state_interface> <state_interface name="effort"> <param name="initial_value">0.0</param> </state_interface> </joint> <joint name="r_joint_a7"> <command_interface name="position"/> <param name="min">-3.05</param> <param name="max">3.05</param> <state_interface name="position"> <param name="initial_value">0.0</param> </state_interface> <state_interface name="velocity"> <param name="initial_value">0.0</param> </state_interface> <state_interface name="effort"> <param name="initial_value">0.0</param> </state_interface> </joint> <sensor name="r_external_torque_sensor"> <state_interface name="external_torque.joint_a1"/> <state_interface name="external_torque.joint_a2"/> <state_interface name="external_torque.joint_a3"/> <state_interface name="external_torque.joint_a4"/> <state_interface name="external_torque.joint_a5"/> <state_interface name="external_torque.joint_a6"/> <state_interface name="external_torque.joint_a7"/> </sensor> </ros2_control> <!-- ros_control plugin --> <gazebo> <plugin filename="libgazebo_ros2_control.so" name="gazebo_ros2_control"> <parameters>/home/malasiot/ros_ws/install/iiwa_description/share/iiwa_description/config/iiwa_controllers.yaml</parameters> </plugin> </gazebo> <!-- ros_control plugin --> <gazebo> <plugin filename="libgazebo_ros2_control.so" name="gazebo_ros2_control"> <parameters>/home/malasiot/ros_ws/install/iiwa_description/share/iiwa_description/config/iiwa_controllers.yaml</parameters> </plugin> </gazebo> </robot>
